<?xml version="1.0"?>
<sdf version="1.4">
  <model name="lifter">
    <link name="back_plane">
      <pose>0 0 0.05 0 0 0</pose>
      <collision name="collision">
        <geometry>
          <box>
            <size>0.8 0.6 0.1</size>
          </box>
        </geometry>
      </collision>
      <visual name="visual">
        <geometry>
          <box>
            <size>0.8 0.8 0.1</size>
          </box>
        </geometry>
      </visual>
    </link>
    <link name="holder_a">
      <pose>-0.3 0.35 0.05 0 -1.5707 0</pose>
      <collision name="collision">
        <geometry>
          <box>
            <size>0.1 0.1 0.6</size>
          </box>
        </geometry>
      </collision>
      <visual name="visual">
        <geometry>
          <box>
            <size>0.1 0.1 0.6</size>
          </box>
        </geometry>
      </visual>
    </link>
    <link name="holder_b">
      <pose>-0.3 -0.35 0.05 0 -1.5707 0</pose>
      <collision name="collision">
        <geometry>
          <box>
            <size>0.1 0.1 0.6</size>
          </box>
        </geometry>
      </collision>
      <visual name="visual">
        <geometry>
          <box>
            <size>0.1 0.1 0.6</size>
          </box>
        </geometry>
      </visual>
    </link>

    <link name="bar_1">
      <pose>0.35 0.2 0.3 0 0 0</pose>
      <collision name="collision">
        <geometry>
          <box>
            <size>0.05 0.05 0.6</size>
          </box>
        </geometry>
      </collision>
      <visual name="visual">
        <geometry>
          <box>
            <size>0.05 0.05 0.6</size>
          </box>
        </geometry>
      </visual>
    </link>

    <link name="bar_2">
      <pose>0.35 -0.2 0.3 0 0 0</pose>
      <collision name="collision">
        <geometry>
          <box>
            <size>0.05 0.05 0.6</size>
          </box>
        </geometry>
      </collision>
      <visual name="visual">
        <geometry>
          <box>
            <size>0.05 0.05 0.6</size>
          </box>
        </geometry>
      </visual>
    </link>

    <joint type="revolute" name="bar_1_joint">
      <pose>0 -0.4 -0.3 0 0 0</pose>
      <child>bar_1</child>
      <parent>back_plane</parent>
      <axis>
        <limit>
          <lower>-1.5707</lower>
          <upper>0</upper>
        </limit>
        <xyz>0 1 0</xyz>
      </axis>
    </joint>

    <joint type="revolute" name="bar_2_joint">
      <pose> 0 0.4 -0.3 0 0 0</pose>
      <child>bar_2</child>
      <parent>back_plane</parent>
      <axis>
        <limit>
          <lower>-1.5707</lower>
          <upper>0</upper>
        </limit>
        <xyz>0 1 0</xyz>
      </axis>
    </joint>

    <joint type="prismatic" name="holder_1_joint">
      <child>holder_a</child>
      <parent>back_plane</parent>
      <axis>
        <limit>
          <lower>-0.4</lower>
          <upper>0</upper>
        </limit>
        <xyz>1 0 0</xyz>
      </axis>
    </joint>
    
    <joint type="prismatic" name="holder_2_joint">
      <child>holder_b</child>
      <parent>back_plane</parent>
      <axis>
        <limit>
          <lower>-0.4</lower>
          <upper>0</upper>
        </limit>
        <xyz>1 0 0</xyz>
      </axis>
    </joint>
 
    <static>true</static>
  </model>
</sdf>

