<?xml version='1.0'?>
<sdf version='1.4'>
  <model name="four_wheeled_car">
    <static>false</static>

    <link name='chassis'>
      <pose>0 0 .25 0 0 0</pose>

      <inertial>
        <mass>20.0</mass>
        <pose>-0.1 0 -0.1 0 0 0</pose>
        <inertia>
          <ixx>0.5</ixx>
          <iyy>1.0</iyy>
          <izz>0.1</izz>
        </inertia>
      </inertial>

      <collision name='collision'>
        <geometry>
          <box>
            <size>1 0.6 0.2</size>
          </box>
        </geometry>
      </collision>

      <visual name='visual'>
        <geometry>
          <box>
            <size>1 0.6 0.2</size>
          </box>
        </geometry>
      </visual>
   </link>
    
    <link name="left_wheel_A">
      <pose>0.3 0.3 0.125 0 1.5707 1.5707</pose>
      <collision name="collision">
        <geometry>
          <cylinder>
            <radius>.125</radius>
            <length>.05</length>
          </cylinder>
        </geometry>
      </collision>

      <visual name="visual">
        <geometry>
          <cylinder>
            <radius>.125</radius>
            <length>.05</length>
          </cylinder>
        </geometry>
      </visual>
    </link>

    <link name="left_wheel_B">
      <pose>-0.3 0.3 0.125 0 1.5707 1.5707</pose>
      <collision name="collision">
        <geometry>
          <cylinder>
            <radius>.125</radius>
            <length>.05</length>
          </cylinder>
        </geometry>
      </collision>

      <visual name="visual">
        <geometry>
          <cylinder>
            <radius>.125</radius>
            <length>.05</length>
          </cylinder>
        </geometry>
      </visual>
    </link>

    <link name="right_wheel_A">
      <pose>0.3 -0.3 0.125 0 1.5707 1.5707</pose>
      <collision name="collision">
        <geometry>
          <cylinder>
            <radius>.125</radius>
            <length>.05</length>
          </cylinder>
        </geometry>
      </collision>
      <visual name="visual">
        <geometry>
          <cylinder>
            <radius>.125</radius>
            <length>.05</length>
          </cylinder>
        </geometry>
      </visual>
    </link>

    <link name="right_wheel_B">
      <pose>-0.3 -0.3 0.125 0 1.5707 1.5707</pose>
      <collision name="collision">
        <geometry>
          <cylinder>
            <radius>.125</radius>
            <length>.05</length>
          </cylinder>
        </geometry>
      </collision>
      <visual name="visual">
        <geometry>
          <cylinder>
            <radius>.125</radius>
            <length>.05</length>
          </cylinder>
        </geometry>
      </visual>
    </link>

    <link name="holder">
      <pose>0.45 0 0.4 0 1.5707 1.5707</pose>
      <collision name="collision">
        <geometry>
          <box>
            <size>0.1 0.1 0.6</size>
          </box>
        </geometry>
      </collision>
      <visual name="visual">
        <geometry>
          <box>
            <size>0.1 0.1 0.6</size>
          </box>
        </geometry>
      </visual>
    </link> 

    <joint type="revolute" name="left_wheel_hinge_A">
      <pose>0 0 -0.03 0 0 0</pose>
      <child>left_wheel_A</child>
      <parent>chassis</parent>
      <axis>
        <xyz>0 1 0</xyz>
      </axis>
    </joint>

    <joint type="revolute" name="left_wheel_hinge_B">
      <pose>0 0 -0.03 0 0 0</pose>
      <child>left_wheel_B</child>
      <parent>chassis</parent>
      <axis>
        <xyz>0 1 0</xyz>
      </axis>
    </joint>

    <joint type="revolute" name="right_wheel_hinge_A">
      <pose>0 0 0.03 0 0 0</pose>
      <child>right_wheel_A</child>
      <parent>chassis</parent>
      <axis>
        <xyz>0 1 0</xyz>
      </axis>
    </joint>

    <joint type="revolute" name="right_wheel_hinge_B">
      <pose>0 0 0.03 0 0 0</pose>
      <child>right_wheel_B</child>
      <parent>chassis</parent>
      <axis>
        <xyz>0 1 0</xyz>
      </axis>
    </joint>

    <joint type="fixed" name="fixed_hoder_joint">
      <pose>0 0 0 0 0 0</pose>
      <child>holder</child>
      <parent>chassis</parent>
    </joint>

  </model>
</sdf>
