<?xml version='1.0'?>
<sdf version='1.4'>
  <model name="body_lifter">
    <static>false</static>

    <link name='chassis'>
      <pose>0 0 .1 0 0 0</pose>

      <collision name='collision'>
        <geometry>
          <box>
            <size>.8 .4 .1</size>
          </box>
        </geometry>
      </collision>

      <visual name='visual'>
        <geometry>
          <box>
            <size>.8 .4 .1</size>
          </box>
        </geometry>
      </visual>

   </link>
    
    <link name="left_wheel_A">
      <pose>0.3 0.23 0.1 0 1.5707 1.5707</pose>
      <collision name="collision">
        <geometry>
          <cylinder>
            <radius>.1</radius>
            <length>.05</length>
          </cylinder>
        </geometry>
      </collision>

      <visual name="visual">
        <geometry>
          <cylinder>
            <radius>.1</radius>
            <length>.05</length>
          </cylinder>
        </geometry>
      </visual>
    </link>

    <link name="left_wheel_B">
      <pose>-0.3 0.23 0.1 0 1.5707 1.5707</pose>
      <collision name="collision">
        <geometry>
          <cylinder>
            <radius>.1</radius>
            <length>.05</length>
          </cylinder>
        </geometry>
      </collision>

      <visual name="visual">
        <geometry>
          <cylinder>
            <radius>.1</radius>
            <length>.05</length>
          </cylinder>
        </geometry>
      </visual>
    </link>

    <link name="right_wheel_A">
      <pose>0.3 -0.23 0.1 0 1.5707 1.5707</pose>
      <collision name="collision">
        <geometry>
          <cylinder>
            <radius>.1</radius>
            <length>.05</length>
          </cylinder>
        </geometry>
      </collision>
      <visual name="visual">
        <geometry>
          <cylinder>
            <radius>.1</radius>
            <length>.05</length>
          </cylinder>
        </geometry>
      </visual>
    </link>

    <link name="right_wheel_B">
      <pose>-0.3 -0.23 0.1 0 1.5707 1.5707</pose>
      <collision name="collision">
        <geometry>
          <cylinder>
            <radius>.1</radius>
            <length>.05</length>
          </cylinder>
        </geometry>
      </collision>
      <visual name="visual">
        <geometry>
          <cylinder>
            <radius>.1</radius>
            <length>.05</length>
          </cylinder>
        </geometry>
      </visual>
    </link>

    <joint type="revolute" name="left_wheel_hinge_A">
      <pose>0 0 -0.03 0 0 0</pose>
      <child>left_wheel_A</child>
      <parent>chassis</parent>
      <axis>
        <xyz>0 1 0</xyz>
      </axis>
    </joint>

    <joint type="revolute" name="left_wheel_hinge_B">
      <pose>0 0 -0.03 0 0 0</pose>
      <child>left_wheel_B</child>
      <parent>chassis</parent>
      <axis>
        <xyz>0 1 0</xyz>
      </axis>
    </joint>

    <joint type="revolute" name="right_wheel_hinge_A">
      <pose>0 0 0.03 0 0 0</pose>
      <child>right_wheel_A</child>
      <parent>chassis</parent>
      <axis>
        <xyz>0 1 0</xyz>
      </axis>
    </joint>

    <joint type="revolute" name="right_wheel_hinge_B">
      <pose>0 0 0.03 0 0 0</pose>
      <child>right_wheel_B</child>
      <parent>chassis</parent>
      <axis>
        <xyz>0 1 0</xyz>
      </axis>
    </joint>

  </model>
</sdf>
